Workbook

Sheet Dashboard
B2: OWASP Mobile Application Security Checklist Based on the OWASP Mobile Application Security Verification Standard 1.0
B10: General Testing Information
B11: Client Name:
B12: Test Location:
B13: Start Date:
B14: Closing Date:
B15: Name of Tester:
B16: Testing Scope | D16: All available functions within the App <AppName>.
B17: Verification Level | D17: After consultation with <Customer> it was decided that only Level 1 requrirements are applicable to <AppName>.
B19: Testing information Android
B20: Application Name:
B21: Google Play Store Link
B22: Filename
B23: Version
B24: MD5 Hash of APK
B26: Testing information iOS
B27: Application Name:
B28: App Store Link
B29: Filename
B30: Version
B31: MD5 Hash of IPA
... B45: E-mail:

Sheet Management Summary
C2: Management Summary
G6: MASVS Compliance Score ( / 5) | V6: MASVS Compliance Score ( / 5)
G8: =AVERAGE(G43:G50)*5 -> #DIV/0! | V8: =AVERAGE(K43:K50)*5 -> #DIV/0!
B20: `
D41: Android | H41: iOS
D42: P | E42: F | F42: NA | G42: % | H42: P | I42: F | J42: NA | K42: %
C43: V1: Architecture, Design and Threat Modelling | D43: =COUNTIFS('Security Requirements - Android'!F5:F14,'Security Requirements - Android'!B79) -> 1 | E43: =COUNTIFS('Security Requirements - Android'!F5:F14,'Security Requirements - Android'!B80) -> 0 | F43: =COUNTIFS('Security Requirements - Android'!F5:F14,'Security Requirements - Android'!B81) -> 6 | G43: =D43/(E43+D43) -> 1 | H43: =COUNTIFS('Security Requirements - iOS'!F5:F14,'Security Requirements - Android'!B79) -> 0 | I43: =COUNTIFS('Security Requirements - iOS'!F5:F14,'Security Requirements - Android'!B80) -> 0 | J43: =COUNTIFS('Security Requirements - iOS'!F5:F14,'Security Requirements - Android'!B81) -> 6 | K43: =H43/(H43+I43) -> #DIV/0!
C44: V2: Data Storage and Privacy | D44: =COUNTIFS('Security Requirements - Android'!F16:F27,'Security Requirements - Android'!B79) -> 0 | E44: =COUNTIFS('Security Requirements - Android'!F16:F27,'Security Requirements - Android'!B80) -> 0 | F44: =COUNTIFS('Security Requirements - Android'!F16:F27,'Security Requirements - Android'!B81) -> 5 | G44: =D44/(E44+D44) -> #DIV/0! | H44: =COUNTIFS('Security Requirements - iOS'!F17:F27,'Security Requirements - Android'!B79) -> 0 | I44: =COUNTIFS('Security Requirements - iOS'!F17:F27,'Security Requirements - Android'!B80) -> 0 | J44: =COUNTIFS('Security Requirements - iOS'!F17:F27,'Security Requirements - Android'!B81) -> 5 | K44: =H44/(H44+I44) -> #DIV/0!
C45: V3: Cryptography Verification | D45: =COUNTIFS('Security Requirements - Android'!F29:F34,'Security Requirements - Android'!B79) -> 0 | E45: =COUNTIFS('Security Requirements - Android'!F29:F34,'Security Requirements - Android'!B80) -> 0 | F45: =COUNTIFS('Security Requirements - Android'!F29:F34,'Security Requirements - Android'!B81) -> 0 | G45: =D45/(E45+D45) -> #DIV/0! | H45: =COUNTIFS('Security Requirements - iOS'!F29:F34,'Security Requirements - Android'!B79) -> 0 | I45: =COUNTIFS('Security Requirements - iOS'!F29:F34,'Security Requirements - Android'!B80) -> 0 | J45: =COUNTIFS('Security Requirements - iOS'!F29:F34,'Security Requirements - Android'!B81) -> 0 | K45: =H45/(H45+I45) -> #DIV/0!
C46: V4: Authentication and Session Management | D46: =COUNTIFS('Security Requirements - Android'!F36:F46,'Security Requirements - Android'!B79) -> 0 | E46: =COUNTIFS('Security Requirements - Android'!F36:F46,'Security Requirements - Android'!B80) -> 0 | F46: =COUNTIFS('Security Requirements - Android'!F36:F46,'Security Requirements - Android'!B81) -> 5 | G46: =D46/(E46+D46) -> #DIV/0! | H46: =COUNTIFS('Security Requirements - iOS'!F36:F46,'Security Requirements - Android'!B79) -> 0 | I46: =COUNTIFS('Security Requirements - iOS'!F36:F46,'Security Requirements - Android'!B80) -> 0 | J46: =COUNTIFS('Security Requirements - iOS'!F36:F46,'Security Requirements - Android'!B81) -> 5 | K46: =H46/(H46+I46) -> #DIV/0!
C47: V5: Network Communication | D47: =COUNTIFS('Security Requirements - Android'!F48:F53,'Security Requirements - Android'!B79) -> 0 | E47: =COUNTIFS('Security Requirements - Android'!F48:F53,'Security Requirements - Android'!B80) -> 0 | F47: =COUNTIFS('Security Requirements - Android'!F48:F53,'Security Requirements - Android'!B81) -> 3 | G47: =D47/(E47+D47) -> #DIV/0! | H47: =COUNTIFS('Security Requirements - iOS'!F48:F53,'Security Requirements - Android'!B79) -> 0 | I47: =COUNTIFS('Security Requirements - iOS'!F48:F53,'Security Requirements - Android'!B80) -> 0 | J47: =COUNTIFS('Security Requirements - iOS'!F48:F53,'Security Requirements - Android'!B81) -> 3 | K47: =H47/(H47+I47) -> #DIV/0!
C48: V6: Platform Interaction | D48: =COUNTIFS('Security Requirements - Android'!F55:F62,'Security Requirements - Android'!B79) -> 0 | E48: =COUNTIFS('Security Requirements - Android'!F55:F62,'Security Requirements - Android'!B80) -> 0 | F48: =COUNTIFS('Security Requirements - Android'!F55:F62,'Security Requirements - Android'!B81) -> 0 | G48: =D48/(E48+D48) -> #DIV/0! | H48: =COUNTIFS('Security Requirements - iOS'!F55:F62,'Security Requirements - Android'!B79) -> 0 | I48: =COUNTIFS('Security Requirements - iOS'!F55:F62,'Security Requirements - Android'!B80) -> 0 | J48: =COUNTIFS('Security Requirements - iOS'!F55:F62,'Security Requirements - Android'!B81) -> 0 | K48: =H48/(H48+I48) -> #DIV/0!
C49: V7: Code Quality and Build Settings | D49: =COUNTIFS('Security Requirements - Android'!F64:F72,'Security Requirements - Android'!B79) -> 0 | E49: =COUNTIFS('Security Requirements - Android'!F64:F72,'Security Requirements - Android'!B80) -> 0 | F49: =COUNTIFS('Security Requirements - Android'!F64:F72,'Security Requirements - Android'!B81) -> 0 | G49: =D49/(E49+D49) -> #DIV/0! | H49: =COUNTIFS('Security Requirements - iOS'!F64:F72,'Security Requirements - Android'!B79) -> 0 | I49: =COUNTIFS('Security Requirements - iOS'!F64:F72,'Security Requirements - Android'!B80) -> 0 | J49: =COUNTIFS('Security Requirements - iOS'!F64:F72,'Security Requirements - Android'!B81) -> 0 | K49: =H49/(H49+I49) -> #DIV/0!
C50: V8: Resiliency Against Reverse Engineering | D50: =COUNTIFS('Anti-RE - Android'!E4:E18,'Security Requirements - Android'!B79) -> 0 | E50: =COUNTIFS('Anti-RE - Android'!E4:E18,'Security Requirements - Android'!B80) -> 0 | F50: =COUNTIFS('Anti-RE - Android'!E4:E18,'Security Requirements - Android'!B81) -> 12 | G50: =D50/(E50+D50) -> #DIV/0! | H50: =COUNTIFS('Anti-RE - iOS'!E4:E18,'Security Requirements - Android'!B79) -> 0 | I50: =COUNTIFS('Anti-RE - iOS'!E4:E18,'Security Requirements - Android'!B80) -> 0 | J50: =COUNTIFS('Anti-RE - iOS'!E4:E18,'Security Requirements - Android'!B81) -> 12 | K50: =H50/(H50+I50) -> #DIV/0!

Sheet Security Requirements - Android
B1: Mobile Application Security Requirements - Android
B3: ID | C3: Detailed Verification Requirement | D3: Level 1 | E3: Level 2 | F3: Status | G3: Testing Procedure | H3: Comment
B4: V1 | C4: Architecture, design and threat modelling
B5: 1.1 | C5: Verify all application components are identified and are known to be needed. | D5: ✓ | E5: ✓ | F5: Pass | G5: -
B6: 1.2 | C6: Verify that security controls are never enforced only on the client side, but on the respective remote endpoints. | D6: ✓ | E6: ✓ | G6: -
B7: 1.3 | C7: Verify that a high-level architecture for the mobile app and all connected remote services has been defined and security has been addressed in that architecture. | D7: ✓ | E7: ✓ | G7: -
B8: 1.4 | C8: Verify that data considered sensitive in the context of the mobile app is clearly identified. | D8: ✓ | E8: ✓ | G8: -
B9: 1.5 | C9: Verify all app components are defined in terms of the business functions and/or security functions they provide. | E9: ✓ | F9: N/A | G9: -
B10: 1.6 | C10: Verify that a threat model for the mobile app and the associated remote services, which identifies potential threats and countermeasures, has been produced. | E10: ✓ | F10: N/A | G10: -
B11: 1.7 | C11: Verify that all security controls have a centralized implementation. | E11: ✓ | F11: N/A | G11: -
B12: 1.8 | C12: Verify that there is an explicit policy for how cryptographic keys (if any) are managed, and the lifecycle of cryptographic keys is enforced. Ideally, follow a key management standard such as NIST SP 800-57. | E12: ✓ | F12: N/A | G12: -
B13: 1.9 | C13: Verify that a mechanism for enforcing updates of the mobile app exists. | E13: ✓ | F13: N/A | G13: -
B14: 1.10 | C14: Verify that security is addressed within all parts of the software development lifecycle. | E14: ✓ | F14: N/A | G14: -
B15: V2 | C15: Data Storage and Privacy
B16: 2.1 | C16: Verify that system credential storage facilities are used appropriately to store sensitive data, such as user credentials or cryptographic keys. | D16: ✓ | E16: ✓ | G16: Testing For Sensitive Data in Local Data Storage
B17: 2.2 | C17: Verify that no sensitive data is written to application logs. | D17: ✓ | E17: ✓ | G17: Testing For Sensitive Data in Logs
B18: 2.3 | C18: Verify that no sensitive data is shared with third parties unless it is a necessary part of the architecture. | D18: ✓ | E18: ✓ | G18: Testing Whether Sensitive Data Is Sent To Third Parties
B19: 2.4 | C19: Verify that the keyboard cache is disabled on text inputs that process sensitive data. | D19: ✓ | E19: ✓ | G19: Testing Whether the Keyboard Cache Is Disabled for Text Input Fields
B20: 2.5 | C20: Verify that the clipboard is deactivated on text fields that may contain sensitive data. | D20: ✓ | E20: ✓ | G20: Testing for Sensitive Data in the Clipboard
B21: 2.6 | C21: Verify that no sensitive data is exposed via IPC mechanisms. | D21: ✓ | E21: ✓ | G21: Testing Whether Sensitive Data Is Exposed via IPC Mechanisms
B22: 2.7 | C22: Verify that no sensitive data, such as passwords or pins, is exposed through the user interface. | D22: ✓ | E22: ✓ | G22: Testing for Sensitive Data Disclosure Through the User Interface
B23: 2.8 | C23: Verify that no sensitive data is included in backups generated by the mobile operating system. | E23: ✓ | F23: N/A | G23: Testing for Sensitive Data in Backups
B24: 2.9 | C24: Verify that the app removes sensitive data from views when backgrounded. | E24: ✓ | F24: N/A | G24: Testing for Sensitive Information in Auto-Generated Screenshots
B25: 2.10 | C25: Verify that the app does not hold sensitive data in memory longer than necessary, and memory is cleared explicitly after use. | E25: ✓ | F25: N/A | G25: Testing for Sensitive Data in Memory
B26: 2.11 | C26: Verify that the app enforces a minimum device-access-security policy, such as requiring the user to set a device passcode. | E26: ✓ | F26: N/A | G26: Testing the Device-Access-Security Policy
B27: 2.12 | C27: Verify that the app educates the user about the types of personally identifiable information processed, as well as security best practices the user should follow in using the app. | E27: ✓ | F27: N/A | G27: Verifying User Education Controls
B28: V3 | C28: Cryptography
B29: 3.1 | C29: Verify that the app does not rely on symmetric cryptography with hardcoded keys as a sole method of encryption. | D29: ✓ | E29: ✓ | G29: Verifying Key Management
B30: 3.2 | C30: Verify that the app uses proven implementations of cryptographic primitives. | D30: ✓ | E30: ✓ | G30: Testing for Custom Implementations of Cryptography
B31: 3.3 | C31: Verify that the app uses cryptographic primitives that are appropriate for the particular use-case, configured with parameters that adhere to industry best practices. | D31: ✓ | E31: ✓ | G31: Verifying the Configuration of Cryptographic Standard Algorithms
B32: 3.4 | C32: Verify that the app does not use cryptographic protocols or algorithms that are widely considered depreciated for security purposes. | D32: ✓ | E32: ✓ | G32: Testing for Insecure and/or Deprecated Cryptographic Algorithms
B33: 3.5 | C33: Verify that the app doesn't re-use the same cryptographic key for multiple purposes. | D33: ✓ | E33: ✓ | G33: Testing Random Number Generation
B34: 3.6 | C34: Verify that all random values are generated using a sufficiently secure random number generator. | D34: ✓ | E34: ✓ | G34: Verifying Key Management
B35: V4 | C35: Authentication and Session Management
B36: 4.1 | C36: Verify that if the app provides users with access to a remote service, an acceptable form of authentication such as username/password authentication is performed at the remote endpoint. | D36: ✓ | E36: ✓ | G36: Verifying that Users Are Properly Authenticated
B37: 4.2 | C37: Verify that the remote endpoint uses randomly generated session identifiers, if classical server side session management is used, to authenticate client requests without sending the user's credentials. | D37: ✓ | E37: ✓ | G37: Testing Session Management
B38: 4.3 | C38: Verify that the remote endpoint uses server side signed tokens, if stateless authentication is used, to authenticate client requests without sending the user's credentials. | D38: ✓ | E38: ✓ | G38: Testing Session Management
B39: 4.4 | C39: Verify that the remote endpoint terminates the existing session when the user logs out. | G39: Testing the Logout Functionality
B40: 4.5 | C40: Verify that a password policy exists and is enforced at the remote endpoint. | D40: ✓ | E40: ✓ | G40: Testing the Password Policy
B41: 4.6 | C41: Verify that the remote endpoint implements a mechanism to protect against the submission of credentials an excessive number of times. | D41: ✓ | E41: ✓ | G41: Testing Excessive Login Attempts
...

Sheet Anti-RE - Android
B1: Resiliency against Reverse Engineering - Android
C3: Resiliency Against Reverse Engineering Requirements | D3: R | E3: Status | F3: Testing Procedure | G3: Comment
C4: Impede Dynamic Analysis and Tampering
B5: 8.1 | C5: Verify that the app implements two or more functionally independent methods of root detection and responds to the presence of a rooted device either by alerting the user or terminating the app. | D5: ✓ | E5: N/A | F5: Testing Advanced Root Detection
B6: 8.2 | C6: Verify that the app implements multiple functionally independent debugging defenses that, in context of the overall protection scheme, force adversaries to invest significant manual effort to enable debugging. All available debugging protocols must be covered (e.g. JDWP and native). | D6: ✓ | E6: N/A | F6: Testing Debugging Defenses
B7: 8.3 | C7: Verify that the app detects, and responds to, tampering with executable files and critical data. | D7: ✓ | E7: N/A | F7: Testing File Integrity Checks
B8: 8.4 | C8: Verify that the app detects the presence of widely used reverse engineering tools, such as code injection tools, hooking frameworks and debugging servers. | D8: ✓ | E8: N/A | F8: Testing Detection of Reverse Engineering Tools
B9: 8.5 | C9: Verify that the app detects, and response to, being run in an emulator using any method. | D9: ✓ | E9: N/A | F9: Testing Simple Emulator Detection
B10: 8.6 | C10: Verify that the app detects, and responds to, modifications of process memory, including relocation table patches and injected code. | D10: ✓ | E10: N/A | F10: Testing Memory Integrity Checks
B11: 8.7 | C11: Verify that the app implements multiple different responses to tampering, debugging and emulation (requirements 8.1 - 8.6), including stealthy responses that don't simply terminate the app. | D11: ✓ | E11: N/A | F11: Verifying the Variability of Tampering Responses
B12: 8.8 | C12: Verify that the detection mechanisms trigger responses of different types, including delayed and stealthy responses. | D12: ✓ | E12: N/A | F12: Testing Detection Mechanisms
B13: 8.9 | C13: Verify that obfuscation is applied to programmatic defenses, which in turn impede de-obfuscation via dynamic analysis. | D13: ✓ | E13: N/A | F13: Testing Simple Obfuscation
C14: Device Binding
B15: 8.10 | C15: Verify that the app implements a 'device binding' functionality when a mobile device is treated as being trusted. Verify that the device fingerprint is derived from multiple device properties. | D15: ✓ | E15: N/A | F15: Testing Device Binding
C16: Impede Comprehension
B17: 8.11 | C17: Verify that all executable files and libraries belonging to the app are either encrypted on the file level and/or important code and data segments inside the executables are encrypted or packed. Trivial static analysis does not reveal important code or data. | D17: ✓ | E17: N/A | F17: Testing Advanced Anti-Emulation
B18: 8.12 | C18: Verify that if the goal of obfuscation is to protect sensitive computations, an obfuscation scheme is used that is both appropriate for the particular task and robust against manual and automated de-obfuscation methods, considering currently published research. The effectiveness of the obfuscation scheme must be verified through manual testing. Note that hardware-based isolation features are prefered over obfuscation whenever possible. | D18: ✓ | E18: N/A | F18: Testing Advanced Obfuscation
B22: Legend
B23: Symbol | C23: Definition
B24: Pass | C24: Requirement is applicable to mobile App and implemented according to best practices.
B25: Fail | C25: Requirement is applicable to mobile App but not fulfilled.
B26: N/A | C26: Requirement is not applicable to mobile App.

Sheet Security Requirements - iOS
B1: Mobile Application Security Requirements - iOS
B3: ID | C3: Detailed Verification Requirement | D3: Level 1 | E3: Level 2 | F3: Status | G3: Testing Procedure | H3: Comment
B4: V1 | C4: Architecture, design and threat modelling
B5: 1.1 | C5: Verify all application components are identified and are known to be needed. | D5: ✓ | E5: ✓ | G5: -
B6: 1.2 | C6: Verify that security controls are never enforced only on the client side, but on the respective remote endpoints. | D6: ✓ | E6: ✓ | G6: -
B7: 1.3 | C7: Verify that a high-level architecture for the mobile app and all connected remote services has been defined and security has been addressed in that architecture. | D7: ✓ | E7: ✓ | G7: -
B8: 1.4 | C8: Verify that data considered sensitive in the context of the mobile app is clearly identified. | D8: ✓ | E8: ✓ | G8: -
B9: 1.5 | C9: Verify all app components are defined in terms of the business functions and/or security functions they provide. | E9: ✓ | F9: N/A | G9: -
B10: 1.6 | C10: Verify that a threat model for the mobile app and the associated remote services, which identifies potential threats and countermeasures, has been produced. | E10: ✓ | F10: N/A | G10: -
B11: 1.7 | C11: Verify that all security controls have a centralized implementation. | E11: ✓ | F11: N/A | G11: -
B12: 1.8 | C12: Verify that there is an explicit policy for how cryptographic keys (if any) are managed, and the lifecycle of cryptographic keys is enforced. Ideally, follow a key management standard such as NIST SP 800-57. | E12: ✓ | F12: N/A | G12: -
B13: 1.9 | C13: Verify that a mechanism for enforcing updates of the mobile app exists. | E13: ✓ | F13: N/A | G13: -
B14: 1.10 | C14: Verify that security is addressed within all parts of the software development lifecycle. | E14: ✓ | F14: N/A | G14: -
B15: V2 | C15: Data Storage and Privacy
B16: 2.1 | C16: Verify that system credential storage facilities are used appropriately to store sensitive data, such as user credentials or cryptographic keys. | D16: ✓ | E16: ✓ | G16: Testing For Sensitive Data in Local Data Storage
B17: 2.2 | C17: Verify that no sensitive data is written to application logs. | D17: ✓ | E17: ✓ | G17: Testing For Sensitive Data in Logs
B18: 2.3 | C18: Verify that no sensitive data is shared with third parties unless it is a necessary part of the architecture. | D18: ✓ | E18: ✓ | G18: Testing Whether Sensitive Data Is Sent To Third Parties
B19: 2.4 | C19: Verify that the keyboard cache is disabled on text inputs that process sensitive data. | D19: ✓ | E19: ✓ | G19: Testing Whether the Keyboard Cache Is Disabled for Text Input Fields
B20: 2.5 | C20: Verify that the clipboard is deactivated on text fields that may contain sensitive data. | D20: ✓ | E20: ✓ | G20: Testing for Sensitive Data in the Clipboard
B21: 2.6 | C21: Verify that no sensitive data is exposed via IPC mechanisms. | D21: ✓ | E21: ✓ | G21: Testing Whether Sensitive Data Is Exposed via IPC Mechanisms
B22: 2.7 | C22: Verify that no sensitive data, such as passwords or pins, is exposed through the user interface. | D22: ✓ | E22: ✓ | G22: Testing for Sensitive Data Disclosure Through the User Interface
B23: 2.8 | C23: Verify that no sensitive data is included in backups generated by the mobile operating system. | E23: ✓ | F23: N/A | G23: Testing for Sensitive Data in Backups
B24: 2.9 | C24: Verify that the app removes sensitive data from views when backgrounded. | E24: ✓ | F24: N/A | G24: Testing for Sensitive Information in Auto-Generated Screenshots
B25: 2.10 | C25: Verify that the app does not hold sensitive data in memory longer than necessary, and memory is cleared explicitly after use. | E25: ✓ | F25: N/A | G25: Testing for Sensitive Data in Memory
B26: 2.11 | C26: Verify that the app enforces a minimum device-access-security policy, such as requiring the user to set a device passcode. | E26: ✓ | F26: N/A | G26: Testing the Device-Access-Security Policy
B27: 2.12 | C27: Verify that the app educates the user about the types of personally identifiable information processed, as well as security best practices the user should follow in using the app. | E27: ✓ | F27: N/A | G27: Verifying User Education Controls
B28: V3 | C28: Cryptography
B29: 3.1 | C29: Verify that the app does not rely on symmetric cryptography with hardcoded keys as a sole method of encryption. | D29: ✓ | E29: ✓ | G29: Verifying Key Management
B30: 3.2 | C30: Verify that the app uses proven implementations of cryptographic primitives. | D30: ✓ | E30: ✓ | G30: Testing for Custom Implementations of Cryptography
B31: 3.3 | C31: Verify that the app uses cryptographic primitives that are appropriate for the particular use-case, configured with parameters that adhere to industry best practices. | D31: ✓ | E31: ✓ | G31: Verifying the Configuration of Cryptographic Standard Algorithms
B32: 3.4 | C32: Verify that the app does not use cryptographic protocols or algorithms that are widely considered depreciated for security purposes. | D32: ✓ | E32: ✓ | G32: Testing for Insecure and/or Deprecated Cryptographic Algorithms
B33: 3.5 | C33: Verify that the app doesn't re-use the same cryptographic key for multiple purposes. | D33: ✓ | E33: ✓ | G33: Testing Random Number Generation
B34: 3.6 | C34: Verify that all random values are generated using a sufficiently secure random number generator. | D34: ✓ | E34: ✓ | G34: Verifying Key Management
B35: V4 | C35: Authentication and Session Management
B36: 4.1 | C36: Verify that if the app provides users with access to a remote service, an acceptable form of authentication such as username/password authentication is performed at the remote endpoint. | D36: ✓ | E36: ✓ | G36: Verifying that Users Are Properly Authenticated
B37: 4.2 | C37: Verify that the remote endpoint uses randomly generated session identifiers, if classical server side session management is used, to authenticate client requests without sending the user's credentials. | D37: ✓ | E37: ✓ | G37: Testing Session Management
B38: 4.3 | C38: Verify that the remote endpoint uses server side signed tokens, if stateless authentication is used, to authenticate client requests without sending the user's credentials. | D38: ✓ | E38: ✓ | G38: Testing the Logout Functionality
B39: 4.4 | C39: Verify that the remote endpoint terminates the existing session when the user logs out. | D39: ✓ | E39: ✓ | G39: Testing the Logout Functionality
B40: 4.5 | C40: Verify that a password policy exists and is enforced at the remote endpoint. | G40: Testing the Password Policy
B41: 4.6 | C41: Verify that the remote endpoint implements a mechanism to protect against the submission of credentials an excessive number of times. | D41: ✓ | E41: ✓ | G41: Testing Excessive Login Attempts
...

Sheet Anti-RE - iOS
B1: Resiliency Against Reverse Engineering - iOS
C3: Resiliency Against Reverse Engineering Requirements | D3: R | E3: Status | F3: Testing Procedure | G3: Comment
C4: Impede Dynamic Analysis and Tampering
B5: 8.1 | C5: Verify that the app implements two or more functionally independent methods of root detection and responds to the presence of a rooted device either by alerting the user or terminating the app. | D5: ✓ | E5: N/A | F5: Testing Advanced Root Detection
B6: 8.2 | C6: Verify that the app implements multiple functionally independent debugging defenses that, in context of the overall protection scheme, force adversaries to invest significant manual effort to enable debugging. All available debugging protocols must be covered (e.g. JDWP and native). | D6: ✓ | E6: N/A | F6: Testing Debugging Defenses
B7: 8.3 | C7: Verify that the app detects, and responds to, tampering with executable files and critical data. | D7: ✓ | E7: N/A | F7: Testing File Integrity Checks
B8: 8.4 | C8: Verify that the app detects the presence of widely used reverse engineering tools, such as code injection tools, hooking frameworks and debugging servers. | D8: ✓ | E8: N/A | F8: Testing Detection of Reverse Engineering Tools
B9: 8.5 | C9: Verify that the app detects, and response to, being run in an emulator using any method. | D9: ✓ | E9: N/A | F9: Testing Simple Emulator Detection
B10: 8.6 | C10: Verify that the app detects, and responds to, modifications of process memory, including relocation table patches and injected code. | D10: ✓ | E10: N/A | F10: Testing Memory Integrity Checks
B11: 8.7 | C11: Verify that the app implements multiple different responses to tampering, debugging and emulation (requirements 8.1 - 8.6), including stealthy responses that don't simply terminate the app. | D11: ✓ | E11: N/A | F11: Verifying the Variability of Tampering Responses
B12: 8.8 | C12: Verify that the detection mechanisms trigger responses of different types, including delayed and stealthy responses. | D12: ✓ | E12: N/A | F12: Testing Detection Mechanisms
B13: 8.9 | C13: Verify that obfuscating transformations and functional defenses are interdependent and well-integrated throughout the app. | D13: ✓ | E13: N/A | F13: Testing Simple Obfuscation
C14: Device Binding
B15: 8.10 | C15: Verify that the app implements a 'device binding' functionality when a mobile device is treated as being trusted. Verify that the device fingerprint is derived from multiple device properties. | D15: ✓ | E15: N/A | F15: Testing Device Binding
C16: Impede Comprehension
B17: 8.11 | C17: Verify that all executable files and libraries belonging to the app are either encrypted on the file level and/or important code and data segments inside the executables are encrypted or packed. Trivial static analysis does not reveal important code or data. | D17: ✓ | E17: N/A | F17: Testing Advanced Anti-Emulation
B18: 8.12 | C18: Verify that if the goal of obfuscation is to protect sensitive computations, an obfuscation scheme is used that is both appropriate for the particular task and robust against manual and automated de-obfuscation methods, considering currently published research. The effectiveness of the obfuscation scheme must be verified through manual testing. Note that hardware-based isolation features are prefered over obfuscation whenever possible. | D18: ✓ | E18: N/A | F18: Testing Advanced Obfuscation
B22: Legend
B23: Symbol | C23: Definition
B24: Pass | C24: Requirement is applicable to mobile App and implemented according to best practices.
B25: Fail | C25: Requirement is applicable to mobile App but not fulfilled.
B26: N/A | C26: Requirement is not applicable to mobile App.

Sheet Version history
A1: XLS Version History
A2: Name | B2: Version | C2: Date | D2: Comment
A3: Alexander Antukh (Opera Software) | B3: 0.1 | C3: 42765 | D3: Initial draft
A4: Sven Schleier | B4: 0.2 | C4: 42766 | D4: Merging of three diffeent templates
A5: Abdessamad Temmar | B5: 0.3 | C5: 42778 | D5: Adding Spider Chart
A6: Bernhard Mueller | B6: 0.8.1 | C6: 42780 | D6: Rework, adding links to Testing Guide
A7: Sven Schleier | B7: 0.9.2 | C7: 42781 | D7: QA (and sync version number with MASVS)
A8: Bernhard Mueller | B8: 0.9.3 | C8: 42829 | D8: Sync with MASVS (merge 7.9 into 7.8)
A9: Sven Schleier | B9: 0.9.3 | C9: 42919 | D9: Sync with MASVS (update requirements of domain 4 and R)
A10: Sven Schleier | B10: 0.9.4 | C10: 42963 | D10: Sync with MASVS (update requirements of domain 1, 4 and 6)
A11: Sven Schleier | B11: 1.0 | C11: 43113 | D11: Sync with MASVS (update requirements of domain 3 and 8)
